Workbook

Sheet ARABALAR
A1: Marka | B1: Model | C1: Tip | D1: Orijin | E1: Cekis_tip | F1: Tavsiye_fiyat | G1: Fatura | H1: Motor_hacmi | I1: Silindir_sayı | J1: Beygir_gucu | K1: Sehir_ici | L1: Sehir_disi | M1: Agirlik | N1: Dingil_aciklik | O1: Uzunluk | P1: k1
A2: Acura | B2: MDX | C2: SUV | D2: Asya | E2: 4*4 | F2: 36945 | G2: 33337 | H2: 3.5 | I2: 6 | J2: 265 | K2: 17 | L2: 23 | M2: 4451 | N2: 106 | O2: 189 | P2: A
A3: Acura | B3: RSX Type S 2dr | C3: Sedan | D3: Asya | E3: Önden | F3: 23820 | G3: 21761 | H3: 2 | I3: 4 | J3: 200 | K3: 24 | L3: 31 | M3: 2778 | N3: 101 | O3: 172 | P3: B
A4: Acura | B4: TSX 4dr | C4: Sedan | D4: Asya | E4: Önden | F4: 26990 | G4: 24647 | H4: 2.4 | I4: 4 | J4: 200 | K4: 22 | L4: 29 | M4: 3230 | N4: 105 | O4: 183 | P4: D
A5: Acura | B5: TL 4dr | C5: Sedan | D5: Asya | E5: Önden | F5: 33195 | G5: 30299 | H5: 3.2 | I5: 6 | J5: 270 | K5: 20 | L5: 28 | M5: 3575 | N5: 108 | O5: 186 | P5: C
A6: Acura | B6: 3.5 RL 4dr | C6: Sedan | D6: Asya | E6: Önden | F6: 43755 | G6: 39014 | H6: 3.5 | I6: 6 | J6: 225 | K6: 18 | L6: 24 | M6: 3880 | N6: 115 | O6: 197 | P6: D
A7: Acura | B7: 3.5 RL w/Navigation 4dr | C7: Sedan | D7: Asya | E7: Önden | F7: 46100 | G7: 41100 | H7: 3.5 | I7: 6 | J7: 225 | K7: 18 | L7: 24 | M7: 3893 | N7: 115 | O7: 197 | P7: B
A8: Acura | B8: NSX coupe 2dr manual S | C8: Sports | D8: Asya | E8: Arkadan | F8: 89765 | G8: 79978 | H8: 3.2 | I8: 6 | J8: 290 | K8: 17 | L8: 24 | M8: 3153 | N8: 100 | O8: 174 | P8: A
A9: Audi | B9: A4 1.8T 4dr | C9: Sedan | D9: Avrupa | E9: Önden | F9: 25940 | G9: 23508 | H9: 1.8 | I9: 4 | J9: 170 | K9: 22 | L9: 31 | M9: 3252 | N9: 104 | O9: 179 | P9: B
A10: Audi | B10: A41.8T convertible 2dr | C10: Sedan | D10: Avrupa | E10: Önden | F10: 35940 | G10: 32506 | H10: 1.8 | I10: 4 | J10: 170 | K10: 23 | L10: 30 | M10: 3638 | N10: 105 | O10: 180 | P10: D
A11: Audi | B11: A4 3.0 4dr | C11: Sedan | D11: Avrupa | E11: Önden | F11: 31840 | G11: 28846 | H11: 3 | I11: 6 | J11: 220 | K11: 20 | L11: 28 | M11: 3462 | N11: 104 | O11: 179 | P11: C
A12: Audi | B12: A4 3.0 Quattro 4dr manual | C12: Sedan | D12: Avrupa | E12: 4*4 | F12: 33430 | G12: 30366 | H12: 3 | I12: 6 | J12: 220 | K12: 17 | L12: 26 | M12: 3583 | N12: 104 | O12: 179 | P12: C
A13: Audi | B13: A4 3.0 Quattro 4dr auto | C13: Sedan | D13: Avrupa | E13: 4*4 | F13: 34480 | G13: 31388 | H13: 3 | I13: 6 | J13: 220 | K13: 18 | L13: 25 | M13: 3627 | N13: 104 | O13: 179 | P13: D
... A22: Audi | B22: RS 6 4dr | C22: Sports | D22: Avrupa | E22: Önden | F22: 84600 | G22: 76417 | H22: 4.2 | I22: 8 | J22: 450 | K22: 15 | L22: 22 | M22: 4024 | N22: 109 | O22: 191 | P22: D
A23: Audi | B23: TT 1.8 convertible 2dr (coupe) | C23: Sports | D23: Avrupa | E23: Önden | F23: 35940 | G23: 32512 | H23: 1.8 | I23: 4 | J23: 180 | K23: 20 | L23: 28 | M23: 3131 | N23: 95 | O23: 159
A24: Audi | B24: TT 1.8 Quattro 2dr (convertible) | C24: Sports | D24: Avrupa | E24: 4*4 | F24: 37390 | G24: 33891 | H24: 1.8 | I24: 4 | J24: 225 | K24: 20 | L24: 28 | M24: 2921 | N24: 96 | O24: 159
A25: Audi | B25: TT 3.2 coupe 2dr (convertible) | C25: Sports | D25: Avrupa | E25: 4*4 | F25: 40590 | G25: 36739 | H25: 3.2 | I25: 6 | J25: 250 | K25: 21 | L25: 29 | M25: 3351 | N25: 96 | O25: 159 | P25: A
A26: Audi | B26: A6 3.0 Avant Quattro | C26: Wagon | D26: Avrupa | E26: 4*4 | F26: 40840 | G26: 37060 | H26: 3 | I26: 6 | J26: 220 | K26: 18 | L26: 25 | M26: 4035 | N26: 109 | O26: 192 | P26: B
A27: Audi | B27: S4 Avant Quattro | C27: Wagon | D27: Avrupa | E27: 4*4 | F27: 49090 | G27: 44446 | H27: 4.2 | I27: 8 | J27: 340 | K27: 15 | L27: 21 | M27: 3936 | N27: 104 | O27: 179 | P27: D
A28: BMW | B28: X3 3.0i | C28: SUV | D28: Avrupa | E28: 4*4 | F28: 37000 | G28: 33873 | H28: 3 | I28: 6 | J28: 225 | K28: 16 | L28: 23 | M28: 4023 | N28: 110 | O28: 180 | P28: C
A29: BMW | B29: X5 4.4i | C29: SUV | D29: Avrupa | E29: 4*4 | F29: 52195 | G29: 47720 | H29: 4.4 | I29: 8 | J29: 325 | K29: 16 | L29: 22 | M29: 4824 | N29: 111 | O29: 184 | P29: D
A30: BMW | B30: 325i 4dr | C30: Sedan | D30: Avrupa | E30: Arkadan | F30: 28495 | G30: 26155 | H30: 2.5 | I30: 6 | J30: 184 | K30: 20 | L30: 29 | M30: 3219 | N30: 107 | O30: 176 | P30: B
A31: BMW | B31: 325Ci 2dr | C31: Sedan | D31: Avrupa | E31: Arkadan | F31: 30795 | G31: 28245 | H31: 2.5 | I31: 6 | J31: 184 | K31: 20 | L31: 29 | M31: 3197 | N31: 107 | O31: 177 | P31: A
A32: BMW | B32: 325Ci convertible 2dr | C32: Sedan | D32: Avrupa | E32: Arkadan | F32: 37995 | G32: 34800 | H32: 2.5 | I32: 6 | J32: 184 | K32: 19 | L32: 27 | M32: 3560 | N32: 107 | O32: 177 | P32: B
A33: BMW | B33: 325xi 4dr | C33: Sedan | D33: Avrupa | E33: 4*4 | F33: 30245 | G33: 27745 | H33: 2.5 | I33: 6 | J33: 184 | K33: 19 | L33: 27 | M33: 3461 | N33: 107 | O33: 176 | P33: A
A34: BMW | B34: 330i 4dr | C34: Sedan | D34: Avrupa | E34: Arkadan | F34: 35495 | G34: 32525 | H34: 3 | I34: 6 | J34: 225 | K34: 20 | L34: 30 | M34: 3285 | N34: 107 | O34: 176 | P34: B
A35: BMW | B35: 330Ci 2dr | C35: Sedan | D35: Avrupa | E35: Arkadan | F35: 36995 | G35: 33890 | H35: 3 | I35: 6 | J35: 225 | K35: 20 | L35: 30 | M35: 3285 | N35: 107 | O35: 176 | P35: D
A36: BMW | B36: 330xi 4dr | C36: Sedan | D36: Avrupa | E36: 4*4 | F36: 37245 | G36: 34115 | H36: 3 | I36: 6 | J36: 225 | K36: 20 | L36: 29 | M36: 3483 | N36: 107 | O36: 176 | P36: C
... A53: Buick | B53: Regal GS 4dr | C53: Sedan | D53: Amerika | E53: Önden | F53: 28345 | G53: 26047 | H53: 3.8 | I53: 6 | J53: 240 | K53: 18 | L53: 28 | M53: 3536 | N53: 109 | O53: 196 | P53: D
A54: Buick | B54: LeSabre Limited 4dr | C54: Sedan | D54: Amerika | E54: Önden | F54: 32245 | G54: 29566 | H54: 3.8 | I54: 6 | J54: 205 | K54: 20 | L54: 29 | M54: 3591 | N54: 112 | O54: 200
A55: Buick | B55: Park Avenue 4dr | C55: Sedan | D55: Amerika | E55: Önden | F55: 35545 | G55: 32244 | H55: 3.8 | I55: 6 | J55: 205 | K55: 20 | L55: 29 | M55: 3778 | N55: 114 | O55: 207
A56: Buick | B56: Park Avenue Ultra 4dr | C56: Sedan | D56: Amerika | E56: Önden | F56: 40720 | G56: 36927 | H56: 3.8 | I56: 6 | J56: 240 | K56: 18 | L56: 28 | M56: 3909 | N56: 114 | O56: 207
A57: Cadillac | B57: Escalade | C57: SUV | D57: Amerika | E57: Önden | F57: 52795 | G57: 48377 | H57: 5.3 | I57: 8 | J57: 295 | K57: 14 | L57: 18 | M57: 5367 | N57: 116 | O57: 199
A58: Cadillac | B58: SRX V8 | C58: SUV | D58: Amerika | E58: Önden | F58: 46995 | G58: 43523 | H58: 4.6 | I58: 8 | J58: 320 | K58: 16 | L58: 21 | M58: 4302 | N58: 116 | O58: 195 | P58: A
A59: Cadillac | B59: CTS VVT 4dr | C59: Sedan | D59: Amerika | E59: Arkadan | F59: 30835 | G59: 28575 | H59: 3.6 | I59: 6 | J59: 255 | K59: 18 | L59: 25 | M59: 3694 | N59: 113 | O59: 190 | P59: B
A60: Cadillac | B60: Deville 4dr | C60: Sedan | D60: Amerika | E60: Önden | F60: 45445 | G60: 41650 | H60: 4.6 | I60: 8 | J60: 275 | K60: 18 | L60: 26 | M60: 3984 | N60: 115 | O60: 207 | P60: A
A61: Cadillac | B61: Deville DTS 4dr | C61: Sedan | D61: Amerika | E61: Önden | F61: 50595 | G61: 46362 | H61: 4.6 | I61: 8 | J61: 300 | K61: 18 | L61: 26 | M61: 4044 | N61: 115 | O61: 207 | P61: B
A62: Cadillac | B62: Seville SLS 4dr | C62: Sedan | D62: Amerika | E62: Önden | F62: 47955 | G62: 43841 | H62: 4.6 | I62: 8 | J62: 275 | K62: 18 | L62: 26 | M62: 3992 | N62: 112 | O62: 201 | P62: D
A63: Cadillac | B63: XLR convertible 2dr | C63: Sports | D63: Amerika | E63: Arkadan | F63: 76200 | G63: 70546 | H63: 4.6 | I63: 8 | J63: 320 | K63: 17 | L63: 25 | M63: 3647 | N63: 106 | O63: 178
A64: Cadillac | B64: Escalade EXT | C64: Truck | D64: Amerika | E64: 4*4 | F64: 52975 | G64: 48541 | H64: 6 | I64: 8 | J64: 345 | K64: 13 | L64: 17 | M64: 5879 | N64: 130 | O64: 221
...

Sheet Sayfa1
A2: Aritmetik Ortalama | F2: =AVERAGE(ARABALAR!F2:F429) -> 32774.855 | G2: =AVERAGE(ARABALAR!G2:G429) -> 30014.701 | H2: =AVERAGE(ARABALAR!H2:H429) -> 3.196729 | I2: =AVERAGE(ARABALAR!I2:I429) -> 5.7943925 | J2: =AVERAGE(ARABALAR!J2:J429) -> 215.88551 | K2: =AVERAGE(ARABALAR!K2:K429) -> 20.060748 | L2: =AVERAGE(ARABALAR!L2:L429) -> 26.843458 | M2: =AVERAGE(ARABALAR!M2:M429) -> 3577.9533 | ... O2: =AVERAGE(ARABALAR!O2:O429) -> 186.36215
A3: Geometrik Ortalama | F3: =GEOMEAN(ARABALAR!F2:F20) -> 39298.703 | G3: =GEOMEAN(ARABALAR!G2:G20) -> 35610.843 | H3: =GEOMEAN(ARABALAR!H2:H20) -> 2.9234442 | I3: =GEOMEAN(ARABALAR!I2:I20) -> 5.6784637 | J3: =GEOMEAN(ARABALAR!J2:J20) -> 230.05675 | K3: =GEOMEAN(ARABALAR!K2:K20) -> 19.042566 | L3: =GEOMEAN(ARABALAR!L2:L20) -> 26.203427 | M3: =GEOMEAN(ARABALAR!M2:M20) -> 3664.2813 | ... O3: =GEOMEAN(ARABALAR!O2:O20) -> 185.43757
A4: Harmonik Ortalama | F4: =HARMEAN(ARABALAR!F2:F429) -> 25837.785 | G4: =HARMEAN(ARABALAR!G2:G20) -> 34098.109 | H4: =HARMEAN(ARABALAR!H2:H20) -> 2.8401384 | I4: =HARMEAN(ARABALAR!I2:I20) -> 5.5609756 | J4: =HARMEAN(ARABALAR!J2:J20) -> 226.83594 | K4: =HARMEAN(ARABALAR!K2:K20) -> 18.933638 | L4: =HARMEAN(ARABALAR!L2:L20) -> 26.09503 | M4: =HARMEAN(ARABALAR!M2:M20) -> 3641.0952 | N4: =HARMEAN(ARABALAR!N2:N20) -> 107.03984 | O4: =HARMEAN(ARABALAR!O2:O20) -> 185.2456
A5: Ortanca (Medyan) | F5: =MEDIAN(ARABALAR!F2:F429) -> 27635 | G5: =MEDIAN(ARABALAR!G2:G429) -> 25294.5 | H5: =MEDIAN(ARABALAR!H2:H429) -> 3 | I5: =MEDIAN(ARABALAR!I2:I429) -> 6 | J5: =MEDIAN(ARABALAR!J2:J429) -> 210 | K5: =MEDIAN(ARABALAR!K2:K429) -> 19 | L5: =MEDIAN(ARABALAR!L2:L429) -> 26 | M5: =MEDIAN(ARABALAR!M2:M429) -> 3474.5 | ... O5: =MEDIAN(ARABALAR!O2:O429) -> 187
A6: Tepe Değeri (Mod) | F6: =MODE(ARABALAR!F2:F429) -> 35940 | G6: =MODE(ARABALAR!G2:G429) -> 14207 | H6: =MODE(ARABALAR!H2:H429) -> 3 | I6: =MODE(ARABALAR!I2:I429) -> 6 | J6: =MODE(ARABALAR!J2:J429) -> 200 | K6: =MODE(ARABALAR!K2:K429) -> 18 | L6: =MODE(ARABALAR!L2:L429) -> 26 | M6: =MODE(ARABALAR!M2:M429) -> 3285 | ... O6: =MODE(ARABALAR!O2:O429) -> 178
A7: Çeyreklik(Q1) | F7: =QUARTILE(ARABALAR!F2:F429,1) -> 20334.25 | G7: =QUARTILE(ARABALAR!G2:G429,1) -> 18866 | H7: =QUARTILE(ARABALAR!H2:H429,1) -> 2.375 | I7: =QUARTILE(ARABALAR!I2:I429,1) -> 4 | J7: =QUARTILE(ARABALAR!J2:J429,1) -> 165 | K7: =QUARTILE(ARABALAR!K2:K429,1) -> 17 | L7: =QUARTILE(ARABALAR!L2:L429,1) -> 24 | M7: =QUARTILE(ARABALAR!M2:M429,1) -> 3104 | ... O7: =QUARTILE(ARABALAR!O2:O429,1) -> 178
A8: Çeyreklik(Q3) | F8: =QUARTILE(ARABALAR!F2:F429,3) -> 39205 | G8: =QUARTILE(ARABALAR!G2:G429,3) -> 35710.25 | H8: =QUARTILE(ARABALAR!H2:H429,3) -> 3.9 | I8: =QUARTILE(ARABALAR!I2:I429,3) -> 6 | J8: =QUARTILE(ARABALAR!J2:J429,3) -> 255 | K8: =QUARTILE(ARABALAR!K2:K429,3) -> 21.25 | L8: =QUARTILE(ARABALAR!L2:L429,3) -> 29 | M8: =QUARTILE(ARABALAR!M2:M429,3) -> 3977.75 | ... O8: =QUARTILE(ARABALAR!O2:O429,3) -> 194
A9: Yüzdelik (%10) | F9: =PERCENTILE(ARABALAR!F2:F429,0.1) -> 15484.5 | G9: =PERCENTILE(ARABALAR!G2:G429,0.1) -> 14459.7 | H9: =PERCENTILE(ARABALAR!H2:H429,0.1) -> 1.8 | I9: =PERCENTILE(ARABALAR!I2:I429,0.1) -> 4 | J9: =PERCENTILE(ARABALAR!J2:J429,0.1) -> 130 | K9: =PERCENTILE(ARABALAR!K2:K429,0.1) -> 15 | L9: =PERCENTILE(ARABALAR!L2:L429,0.1) -> 20 | M9: =PERCENTILE(ARABALAR!M2:M429,0.1) -> 2678.7 | ... O9: =PERCENTILE(ARABALAR!O2:O429,0.1) -> 168
A10: Minimum Değer | F10: =MIN(ARABALAR!F2:F429) -> 10280 | G10: =MIN(ARABALAR!G2:G429) -> 9875 | H10: =MIN(ARABALAR!H2:H429) -> 1.3 | I10: =MIN(ARABALAR!I2:I429) -> 3 | J10: =MIN(ARABALAR!J2:J429) -> 73 | K10: =MIN(ARABALAR!K2:K429) -> 10 | L10: =MIN(ARABALAR!L2:L429) -> 12 | M10: =MIN(ARABALAR!M2:M429) -> 1850 | ... O10: =MIN(ARABALAR!O2:O429) -> 143
A11: Maksimum Değer | F11: =MAX(ARABALAR!F2:F429) -> 192465 | G11: =MAX(ARABALAR!G2:G429) -> 173560 | H11: =MAX(ARABALAR!H2:H429) -> 8.3 | I11: =MAX(ARABALAR!I2:I429) -> 12 | J11: =MAX(ARABALAR!J2:J429) -> 500 | K11: =MAX(ARABALAR!K2:K429) -> 60 | L11: =MAX(ARABALAR!L2:L429) -> 66 | M11: =MAX(ARABALAR!M2:M429) -> 7190 | ... O11: =MAX(ARABALAR!O2:O429) -> 238
A12: Dağılım Genişliği | F12: =MAX(ARABALAR!F2:F429)-MIN(ARABALAR!F2:F429) -> 182185 | G12: =MAX(ARABALAR!G2:G429)-MIN(ARABALAR!G2:G429) -> 163685 | H12: =MAX(ARABALAR!H2:H429)-MIN(ARABALAR!H2:H429) -> 7 | I12: =MAX(ARABALAR!I2:I429)-MIN(ARABALAR!I2:I429) -> 9 | J12: =MAX(ARABALAR!J2:J429)-MIN(ARABALAR!J2:J429) -> 427 | K12: =MAX(ARABALAR!K2:K429)-MIN(ARABALAR!K2:K429) -> 50 | L12: =MAX(ARABALAR!L2:L429)-MIN(ARABALAR!L2:L429) -> 54 | M12: =MAX(ARABALAR!M2:M429)-MIN(ARABALAR!M2:M429) -> 5340 | ... O12: =MAX(ARABALAR!O2:O429)-MIN(ARABALAR!O2:O429) -> 95
A13: Çeyreklikler Arası Genişlik | F13: =QUARTILE(ARABALAR!F2:F429,3)-QUARTILE(ARABALAR!F2:F429,1) -> 18870.75 | G13: =QUARTILE(ARABALAR!G2:G429,3)-QUARTILE(ARABALAR!G2:G429,1) -> 16844.25 | H13: =QUARTILE(ARABALAR!H2:H429,3)-QUARTILE(ARABALAR!H2:H429,1) -> 1.525 | I13: =QUARTILE(ARABALAR!I2:I429,3)-QUARTILE(ARABALAR!I2:I429,1) -> 2 | J13: =QUARTILE(ARABALAR!J2:J429,3)-QUARTILE(ARABALAR!J2:J429,1) -> 90 | K13: =QUARTILE(ARABALAR!K2:K429,3)-QUARTILE(ARABALAR!K2:K429,1) -> 4.25 | L13: =QUARTILE(ARABALAR!L2:L429,3)-QUARTILE(ARABALAR!L2:L429,1) -> 5 | M13: =QUARTILE(ARABALAR!M2:M429,3)-QUARTILE(ARABALAR!M2:M429,1) -> 873.75 | ... O13: =QUARTILE(ARABALAR!O2:O429,3)-QUARTILE(ARABALAR!O2:O429,1) -> 16
A14: Varyans | F14: =VAR(ARABALAR!F2:F429) -> 3.7759161e+08 | G14: =VAR(ARABALAR!G2:G429) -> 3.1124432e+08 | H14: =VAR(ARABALAR!H2:H429) -> 1.2289822 | I14: =VAR(ARABALAR!I2:I429) -> 2.4541137 | J14: =VAR(ARABALAR!J2:J429) -> 5160.4154 | K14: =VAR(ARABALAR!K2:K429) -> 27.438924 | L14: =VAR(ARABALAR!L2:L429) -> 32.961386 | M14: =VAR(ARABALAR!M2:M429) -> 576055.52 | ... O14: =VAR(ARABALAR!O2:O429) -> 206.15191
A15: Standart Sapma | F15: =STDEV(ARABALAR!F2:F429) -> 19431.717 | G15: =STDEV(ARABALAR!G2:G429) -> 17642.118 | H15: =STDEV(ARABALAR!H2:H429) -> 1.1085947 | I15: =STDEV(ARABALAR!I2:I429) -> 1.5665611 | J15: =STDEV(ARABALAR!J2:J429) -> 71.836032 | K15: =STDEV(ARABALAR!K2:K429) -> 5.2382176 | L15: =STDEV(ARABALAR!L2:L429) -> 5.7412007 | M15: =STDEV(ARABALAR!M2:M429) -> 758.98321 | ... O15: =STDEV(ARABALAR!O2:O429) -> 14.357991
A16: Değişim Katsayısı | F16: =F15/F2*100 -> 59.28849 | G16: =G15/G2*100 -> 58.778256 | H16: =H15/H2*100 -> 34.679034 | I16: =I15/I2*100 -> 27.035813 | J16: =J15/J2*100 -> 33.275059 | K16: =K15/K2*100 -> 26.111777 | L16: =L15/L2*100 -> 21.387709 | M16: =M15/M2*100 -> 21.212776 | ... O16: =O15/O2*100 -> 7.7043495
A17: Çarpıklık | F17: =SKEW(ARABALAR!F2:F429) -> 2.7980993 | G17: =SKEW(ARABALAR!G2:G429) -> 2.8347404 | H17: =SKEW(ARABALAR!H2:H429) -> 0.70815198 | I17: =SKEW(ARABALAR!I2:I429) -> 0.5790257 | J17: =SKEW(ARABALAR!J2:J429) -> 0.93033074 | K17: =SKEW(ARABALAR!K2:K429) -> 2.7820718 | L17: =SKEW(ARABALAR!L2:L429) -> 1.2523953 | M17: =SKEW(ARABALAR!M2:M429) -> 0.89182423 | ... O17: =SKEW(ARABALAR!O2:O429) -> 0.18197703
A18: Basıklık | F18: =KURT(ARABALAR!F2:F429) -> 13.879206 | G18: =KURT(ARABALAR!G2:G429) -> 13.946164 | H18: =KURT(ARABALAR!H2:H429) -> 0.54194354 | I18: =KURT(ARABALAR!I2:I429) -> 0.42132526 | J18: =KURT(ARABALAR!J2:J429) -> 1.5521586 | K18: =KURT(ARABALAR!K2:K429) -> 15.791147 | L18: =KURT(ARABALAR!L2:L429) -> 6.0456107 | M18: =KURT(ARABALAR!M2:M429) -> 1.6887885 | ... O18: =KURT(ARABALAR!O2:O429) -> 0.61472451
A19: Standart Sapma Yöntemi | C19: Üst | F19: =F2+2*F15 -> 71638.288 | G19: =G2+2*G15 -> 65298.936 | H19: =H2+2*H15 -> 5.4139184 | I19: =I2+2*I15 -> 8.9275147 | J19: =J2+2*J15 -> 359.55758 | K19: =K2+2*K15 -> 30.537183 | L19: =L2+2*L15 -> 38.325859 | M19: =M2+2*M15 -> 5095.9197 | ... O19: =O2+2*O15 -> 215.07813
A20: Standart Sapma Yöntemi | C20: Alt | F20: =F2-2*F15 -> -6088.5782 | G20: =G2-2*G15 -> -5269.5346 | H20: =H2-2*H15 -> 0.97953954 | I20: =I2-2*I15 -> 2.6612703 | J20: =J2-2*J15 -> 72.213451 | K20: =K2-2*K15 -> 9.5843124 | L20: =L2-2*L15 -> 15.361057 | M20: =M2-2*M15 -> 2059.9868 | ... O20: =O2-2*O15 -> 157.64617
A21: Box-Plot (Tukey) Yöntemi | C21: Üst | F21: =F7+1.5*(F8-F7) -> 48640.375 | G21: =G7+1.5*(G8-G7) -> 44132.375 | H21: =H7+1.5*(H8-H7) -> 4.6625 | I21: =I7+1.5*(I8-I7) -> 7 | J21: =J7+1.5*(J8-J7) -> 300 | K21: =K7+1.5*(K8-K7) -> 23.375 | L21: =L7+1.5*(L8-L7) -> 31.5 | M21: =M7+1.5*(M8-M7) -> 4414.625 | ... O21: =O7+1.5*(O8-O7) -> 202
A22: Box-Plot (Tukey) Yöntemi | C22: Alt | F22: =F7-1.5*(F8-F7) -> -7971.875 | G22: =G7-1.5*(G8-G7) -> -6400.375 | H22: =H7-1.5*(H8-H7) -> 0.0875 | I22: =I7-1.5*(I8-I7) -> 1 | J22: =J7-1.5*(J8-J7) -> 30 | K22: =K7-1.5*(K8-K7) -> 10.625 | L22: =L7-1.5*(L8-L7) -> 16.5 | M22: =M7-1.5*(M8-M7) -> 1793.375 | ... O22: =O7-1.5*(O8-O7) -> 154
A23: Medyan Yöntemi | C23: Üst | F23: =F5+2*(F8-F7) -> 65376.5 | G23: =G5+2*(G8-G7) -> 58983 | H23: =H5+2*(H8-H7) -> 6.05 | I23: =I5+2*(I8-I7) -> 10 | J23: =J5+2*(J8-J7) -> 390 | K23: =K5+2*(K8-K7) -> 27.5 | L23: =L5+2*(L8-L7) -> 36 | M23: =M5+2*(M8-M7) -> 5222 | ... O23: =O5+2*(O8-O7) -> 219
A24: Medyan Yöntemi | C24: Alt | F24: =F5-2*(F8-F7) -> -10106.5 | G24: =G5-2*(G8-G7) -> -8394 | H24: =H5-2*(H8-H7) -> -0.05 | I24: =I5-2*(I8-I7) -> 2 | J24: =J5-2*(J8-J7) -> 30 | K24: =K5-2*(K8-K7) -> 10.5 | L24: =L5-2*(L8-L7) -> 16 | M24: =M5-2*(M8-M7) -> 1727 | ... O24: =O5-2*(O8-O7) -> 155
A25: Sturges Formülü | C25: =1+3.3*LOG(428) -> 9.6837644
A26: Korelasyon | C26: =CORREL(ARABALAR!H1:H429,ARABALAR!M1:M429) -> 0.80786674 | D26: Motor Hacmi - Ağırlık Korelasyonu
A27: Kovaryans | C27: =COVAR(ARABALAR!H1:H429,ARABALAR!M1:M429) -> 678.15475 | D27: Motor Hacmi - Ağırlık Korelasyonu
